<?xml version="1.0" ?>

<robot name="iRobot" xmlns:xacro="http://www.ros.org/wiki/xacro">
  <!-- MODELS -->
  <material name="iRobot/Green">
    <color rgba="0.0 1.0 0.0 1.0"/>
  </material>
  <material name="iRobot/Yellow">
    <color rgba="1.0 1.0 0.0 1.0"/>
  </material>
  <material name="iRobot/LightYellow">
    <color rgba="1.0 1.0 0.6 1.0"/>
  </material>
  <material name="iRobot/Blue">
    <color rgba="0.0 0.0 1.0 1.0"/>
  </material>
  <material name="iRobot/LightBlue">
    <color rgba="0.6 0.79 1.0 1.0"/>
  </material>
  <material name="iRobot/DarkGrey">
    <color rgba="0.31 0.31 0.31 1.0"/>
  </material>
  <material name="iRobot/LightGrey">
    <color rgba="0.83 0.83 0.83 1.0"/>
  </material>
  <material name="iRobot/MediumGrey">
    <color rgba="0.5 0.5 0.5 1.0"/>
  </material>
  <material name="iRobot/Black">
    <color rgba="0.0 0.0 0.0 1.0"/>
  </material>
  <material name="iRobot/Red">
    <color rgba="1.0 0.0 0.0 1.0"/>
  </material>
  <material name="iRobot/Orange">
    <color rgba="1.0 0.65 0.0 1.0"/>
  </material>
  
  <link name="robot_footprint"/>
  <joint name="ahla_joint_1" type="fixed">
      <origin xyz="0 0 0" rpy="0 0 0"/>
      <parent link="robot_footprint"/>
      <child link="base_link" />
  </joint>
  
  <link name="base_link">
    <inertial>
      <origin rpy="0 0 0" xyz="0 0 0"/>
      <mass value="0"/>
      <inertia ixx="0.0" ixy="0.0" ixz="0.0" iyy="0.0" iyz="0.0" izz="0.0"/>
    </inertial>
  </link>
  <joint name="base_joint" type="fixed">
    <origin rpy="0 0 0" xyz="0 0 0"/>
    <parent link="base_link"/>
    <child link="chassis"/>
  </joint>

  <link name="chassis">
    <inertial>
      <origin xyz="0 0 0"/>
      <mass value="4"/>
      <inertia ixx="0.425" ixy="0" ixz="0" iyy="0.425" iyz="0" izz="0.85"/>
    </inertial>
    <visual>
      <origin xyz="0 0 0"/>
      <geometry>
        <box size="0.35 0.35 0.15"/>
      </geometry>
      <material name="iRobot/LightGrey"/>
    </visual>
    <collision>
      <origin xyz="0 0 0"/>
      <geometry>
        <box size="0.35 0.35 0.15"/>
      </geometry>
    </collision>
  </link>
  
  <joint name="lidar_joint" type="fixed">
    <origin xyz="0 0 0.08" rpy=" 0  0 0" />
    <parent link="chassis" />
    <child link="chassis_dummy" />
    <axis xyz="0 0 0.08" />
  </joint>
  
 <link name="chassis_dummy">
    <inertial>
      <origin xyz="0 0 0"/>
      <mass value="0.8"/>
      <inertia ixx="0.425" ixy="0" ixz="0" iyy="0.425" iyz="0" izz="0.85"/>
    </inertial>
    <visual>
      <origin xyz="0 0 0"/>
      <geometry>
        <box size="0.35 0.35 0.11"/>
      </geometry>
      <material name="iRobot/LightGrey"/>
    </visual>
    <collision>
      <origin xyz="0 0 0"/>
      <geometry>
        <box size="0.35 0.35 0.11"/>
      </geometry>
    </collision>
 </link>


  <joint name="left_axis_base_joint" type="fixed">
    <origin rpy="0 0 0" xyz="0 0.175 -0.0375"/>
    <parent link="chassis"/>
    <child link="left_axis"/>
  </joint>

  <link name="left_axis">
    <inertial>
      <origin rpy="-1.57079632679 0 0" xyz="0 0 0"/>
      <mass value="0.001"/>
      <inertia ixx="6.25e-07" ixy="0.0" ixz="0.0" iyy="6.25e-07" iyz="0.0" izz="2.08333333333e-07"/>
    </inertial>
    <visual>
      <origin rpy="-1.57079632679 0 0" xyz="0 0 0"/>
      <geometry>
        <cylinder length="0.04" radius="0.0025"/>
      </geometry>
      <material name="iRobot/LightGrey"/>
    </visual>
    <collision>
      <origin rpy="-1.57079632679 0 0" xyz="0 0 0"/>
      <geometry>
        <cylinder length="0.04" radius="0.0025"/>
      </geometry>
    </collision>
  </link>
 
  <joint name="left_wheel_rot_joint" type="continuous">
    <origin rpy="0 0 0" xyz="0 0.02 0"/>
    <axis xyz="0 1 0"/>
    <limit effort="100" velocity="100"/>
    <joint_properties damping="0.0" friction="0.0"/>
    <parent link="left_axis"/>
    <child link="left_wheel_link"/>
  </joint>

  <link name="left_wheel_link">
    <inertial>
      <origin rpy="-1.57079632679 0 0" xyz="0 0.01 0"/>
      <mass value="0.5"/>
      <inertia ixx="0.00375" ixy="0.0" ixz="0.0" iyy="0.00375" iyz="0.0" izz="0.00125"/>
    </inertial>
    <visual>
      <origin rpy="-1.57079632679 0 0" xyz="0 0 0"/>
      <geometry>
        <cylinder length="0.02" radius="0.065"/>
      </geometry>
      <material name="iRobot/Black"/>
    </visual>
    <collision>
      <origin rpy="-1.57079632679 0 0" xyz="0 0 0"/>
      <geometry>
        <cylinder length="0.02" radius="0.065"/>
      </geometry>
    </collision>
  </link>

  
  <joint name="right_axis_base_joint" type="fixed">
    <origin rpy="0 0 0" xyz="0 -0.175 -0.0375"/>
    <parent link="chassis"/>
    <child link="right_axis"/>
  </joint>
  
  <link name="right_axis">
    <inertial>
      <origin rpy="-1.57079632679 0 0" xyz="0 0 0"/>
      <mass value="0.001"/>
      <inertia ixx="6.25e-07" ixy="0.0" ixz="0.0" iyy="6.25e-07" iyz="0.0" izz="2.08333333333e-07"/>
    </inertial>
    <visual>
      <origin rpy="-1.57079632679 0 0" xyz="0 0 0"/>
      <geometry>
        <cylinder length="0.04" radius="0.0025"/>
      </geometry>
      <material name="iRobot/LightGrey"/>
    </visual>
    <collision>
      <origin rpy="-1.57079632679 0 0" xyz="0 0 0"/>
      <geometry>
        <cylinder length="0.04" radius="0.0025"/>
      </geometry>
    </collision>
  </link>
 
  <joint name="right_wheel_rot_joint" type="continuous">
    <origin rpy="0 0 0" xyz="0 -0.02 0"/>
    <axis xyz="0 1 0"/>
    <limit effort="100" velocity="100"/>
    <joint_properties damping="0.0" friction="0.0"/>
    <parent link="right_axis"/>
    <child link="right_wheel_link"/>
  </joint>
  
  <link name="right_wheel_link">
    <inertial>
      <origin rpy="-1.57079632679 0 0" xyz="0 0.01 0"/>
      <mass value="0.5"/>
      <inertia ixx="0.00375" ixy="0.0" ixz="0.0" iyy="0.00375" iyz="0.0" izz="0.00125"/>
    </inertial>
    <visual>
      <origin rpy="-1.57079632679 0 0" xyz="0 0 0"/>
      <geometry>
        <cylinder length="0.02" radius="0.065"/>
      </geometry>
      <material name="iRobot/Black"/>
    </visual>
    <collision>
      <origin rpy="-1.57079632679 0 0" xyz="0 0 0"/>
      <geometry>
        <cylinder length="0.02" radius="0.065"/>
      </geometry>
    </collision>
  </link>
 
  <joint name="sphere_joint1" type="revolute">
    <origin rpy="0 0 0" xyz="-0.175 0 -0.08875"/>
    <axis xyz="0 0 1"/>
    <limit effort="100" lower="0" upper="0" velocity="100"/>
    <parent link="chassis"/>
    <child link="sphere1"/>
  </joint>
  
  <link name="sphere1">
    <inertial>
      <origin rpy="0 0 0" xyz="0 0 0"/>
      <mass value="0.3"/>
      <inertia ixx="0.0012" ixy="0.0" ixz="0.0" iyy="0.0012" iyz="0.0" izz="0.0012"/>
    </inertial>
    <visual>
      <origin rpy="0 0 0" xyz="0 0 0"/>
      <geometry>
        <sphere radius="0.01375"/>
      </geometry>
      <material name="iRobot/Black"/>
    </visual>
    <collision>
      <origin rpy="0 0 0" xyz="0 0 0"/>
      <geometry>
        <sphere radius="0.01375"/>
      </geometry>
    </collision>
  </link>
  
  <joint name="sphere_joint2" type="revolute">
    <origin rpy="0 0 0" xyz="0.175 0 -0.08875"/>
    <axis xyz="0 0 1"/>
    <limit effort="100" lower="0" upper="0" velocity="100"/>
    <parent link="chassis"/>
    <child link="sphere2"/>
  </joint>
  
  <link name="sphere2">
    <inertial>
      <origin rpy="0 0 0" xyz="0 0 0"/>
      <mass value="0.3"/>
      <inertia ixx="0.0012" ixy="0.0" ixz="0.0" iyy="0.0012" iyz="0.0" izz="0.0012"/>
    </inertial>
    <visual>
      <origin rpy="0 0 0" xyz="0 0 0"/>
      <geometry>
        <sphere radius="0.01375"/>
      </geometry>
      <material name="iRobot/Black"/>
    </visual>
    <collision>
      <origin rpy="0 0 0" xyz="0 0 0"/>
      <geometry>
        <sphere radius="0.01375"/>
      </geometry>
    </collision>
  </link>
  <!-- Laser link and plugin 
  
  0 0 0 0 -0.0259
  -->
  
  <joint name="hokuyo_laser_joint" type="fixed">
    <axis xyz="0 0 0"/>
    <origin xyz="0 0 0" rpy="0 0 -1.57" />
    <parent link="chassis_dummy"/>
    <child link="hokuyo_laser_link"/>
  </joint>
  

  <link name="hokuyo_laser_link">
    <visual>
      <origin rpy="0 0 0" xyz="0.25 0.19 -0.0259"/>
      <geometry>
        <mesh filename="package://robot_description/stl/RpLidar.stl" scale="0.001 0.001 0.001"/> 
      </geometry>
      <material name="blue"/>
    </visual>
    <collision>
      <origin rpy="0 0 0" xyz="0.25 0.19 -0.0259"  />
      <geometry>
        <mesh filename="package://robot_description/stl/RpLidar.stl" scale="0.001 0.001 0.001" />
      </geometry>
    </collision>
  </link>  
  
  



 

  <link name="imu_link">
    <inertial>
      <origin xyz="0.0 0.0 0.0" rpy="0 0 0" />
      <mass value="0.000528415362211671" />
      <inertia ixx="1.46176048428261E-08" ixy="1.40015117949421E-10" ixz="-1.99633872937403E-12"
               iyy="8.59662482954888E-09" iyz="7.52375112767959E-12"
               izz="2.30279421279312E-08" />
    </inertial>
    <visual>
      <origin xyz="0 0 0" rpy="1.5708 0 1.5708" />
      <geometry>
        <mesh filename="package://robot_description/stl/imu_link.STL" />
      </geometry>
    </visual>
    <collision>
      <origin xyz="0 0 0" rpy="1.5708 0 1.5708" />
      <geometry>
        <mesh filename="package://robot_description/stl/imu_link.STL" />
      </geometry>
    </collision>
  </link>

  <joint name="imu_joint" type="fixed">
    <origin xyz="0.160 0 -0.055" rpy="  0  1.5708 0" />
    <parent link="base_link" />
    <child link="imu_link" />
    <axis xyz="0.160 0 -0.055" />
  </joint>
  
  <link name="leg1">
    <inertial>
      <origin xyz="0 0 0"/>
      <mass value="1"/>
      <inertia ixx="0.425" ixy="0" ixz="0" iyy="0.425" iyz="0" izz="0.85"/>
    </inertial>
    <visual>
      <origin xyz="0 0 0.1"/>
      <geometry>
        <cylinder length="0.3" radius="0.032"/> <!-- A rod as a leg -->
      </geometry>
      <material name="iRobot/LightGrey"/>
    </visual>
    <collision>
      <origin xyz="0 0 0"/>
      <geometry>
        <cylinder length="0.3" radius="0.02"/> <!-- A rod as a leg -->
      </geometry>
    </collision>
  </link>
  
  <joint name="leg_joint" type="fixed">
    <origin xyz="0 0.0655 0.1" rpy="  0  0 0" />
    <parent link="chassis_dummy" />
    <child link="leg1" />
    <axis xyz="0 0 0" />
  </joint>
  
  <link name="leg2">
    <inertial>
      <origin xyz="0 0 0"/>
      <mass value="1"/>
      <inertia ixx="0.425" ixy="0" ixz="0" iyy="0.425" iyz="0" izz="0.85"/>
    </inertial>
    <visual>
      <origin xyz="0 0 0.1"/>
      <geometry>
        <cylinder length="0.3" radius="0.032"/> <!-- A rod as a leg -->
      </geometry>
      <material name="iRobot/LightGrey"/>
    </visual>
    <collision>
      <origin xyz="0 0 0"/>
      <geometry>
        <cylinder length="0.3" radius="0.02"/> <!-- A rod as a leg -->
      </geometry>
    </collision>
  </link>
  
  <joint name="leg_joint2" type="fixed">
    <origin xyz="0 -0.0655 0.1" rpy="  0  0 0" />
    <parent link="chassis_dummy" />
    <child link="leg2" />
    <axis xyz="0 0 0" />
  </joint>
  <link name="chest1">
    <inertial>
      <origin xyz="0 0 0"/>
      <mass value="1"/>
      <inertia ixx="0.425" ixy="0" ixz="0" iyy="0.425" iyz="0" izz="0.85"/>
    </inertial>
    <visual>
      <origin xyz="0 0 0"/>
      <geometry>
        <box size="0.125 0.138 0.22"/>
      </geometry>
      <material name="iRobot/LightGrey"/>
    </visual>
    <collision>
      <origin xyz="0 0 0"/>
      <geometry>
        <box size="0.125 0.138 0.22"/>
      </geometry>
    </collision>
  </link>
  
  <joint name="chest_joint1" type="fixed">
    <origin xyz="0 0 0.2" rpy="  0  0 0" />
    <parent link="leg1" />
    <child link="chest1" />
    <axis xyz="0 0 0" />
  </joint>
  <link name="chest2">
    <inertial>
      <origin xyz="0 0 0"/>
      <mass value="1"/>
      <inertia ixx="0.425" ixy="0" ixz="0" iyy="0.425" iyz="0" izz="0.85"/>
    </inertial>
    <visual>
      <origin xyz="0 0 0"/>
      <geometry>
        <box size="0.125 0.138 0.22"/>
      </geometry>
      <material name="iRobot/LightGrey"/>
    </visual>
    <collision>
      <origin xyz="0 0 0"/>
      <geometry>
        <box size="0.125 0.138 0.22"/>
      </geometry>
    </collision>
  </link>
  
  <joint name="chest_joint2" type="fixed">
    <origin xyz="0 0 0.2" rpy="  0  0 0" />
    <parent link="leg2" />
    <child link="chest2" />
    <axis xyz="0 0 0" />
  </joint>
  <link name="head">
    <inertial>
      <origin xyz="0 0 0"/>
      <mass value="0,3"/>
      <inertia ixx="0.425" ixy="0" ixz="0" iyy="0.425" iyz="0" izz="0.85"/>
    </inertial>
    <visual>
      <origin xyz="0 0 0"/>
      <geometry>
        <sphere radius="0.06"/>
      </geometry>
      <material name="iRobot/LightGrey"/>
    </visual>
    <collision>
      <origin xyz="0 0 0"/>
      <geometry>
        <sphere radius="0.06"/>
      </geometry>
    </collision>
  </link>
  
  <joint name="head_joint2" type="fixed">
    <origin xyz="0 0.0625 0.17" rpy="  0  0 0" />
    <parent link="chest2" />
    <child link="head" />
    <axis xyz="0 0 0" />
  </joint>

	<transmission name="left_wheel_transmission">
	  <type>transmission_interface/SimpleTransmission</type>
	  <joint name="left_wheel_rot_joint">
	    <hardwareInterface>hardware_interface/VelocityJointInterface</hardwareInterface>
	  </joint>
	  <actuator name="left_wheel_actuator">
	    <mechanicalReduction>19.7</mechanicalReduction>
	    <hardwareInterface>hardware_interface/VelocityJointInterface</hardwareInterface>
	  </actuator>
	</transmission>

	<transmission name="right_wheel_transmission">
	  <type>transmission_interface/SimpleTransmission</type>
	  <joint name="right_wheel_rot_joint">
	    <hardwareInterface>hardware_interface/VelocityJointInterface</hardwareInterface>
	  </joint>
	  <actuator name="right_wheel_actuator">
	    <mechanicalReduction>19.7</mechanicalReduction>
	    <hardwareInterface>hardware_interface/VelocityJointInterface</hardwareInterface>
	  </actuator>
	</transmission>
	
	<gazebo>

      <plugin name="gazebo_ros_control" filename="libgazebo_ros_control.so">
    		<robotNamespace>/rrbot</robotNamespace>
    		<legacyModeNS>true</legacyModeNS>
  		</plugin>
	</gazebo>

</robot>
